<?xml version="1.0" encoding="utf-8"?>
<!-- This URDF was automatically created by SolidWorks to URDF Exporter! -->
<robot
  name="segway">
  <link
    name="chejia_link">
    <inertial>
      <origin
        xyz="0.00361762800581263 -0.133421165022722 0.0648164589836014"
        rpy="0 0 0" />
      <mass
        value="2.42397545608915" />
      <inertia
        ixx="0.0296962022350776"
        ixy="2.4976120795965E-06"
        ixz="-1.37689680267216E-05"
        iyy="0.0331663553221158"
        iyz="3.0593217918394E-05"
        izz="0.00646533575042488" />
    </inertial>
    <visual>
      <origin
        xyz="0 0 0"
        rpy="0 0 0" />
      <geometry>
        <mesh
          filename="package://segway_description/meshes/chejia_link.STL" />
      </geometry>
      <material
        name="">
        <color
          rgba="0.792156862745098 0.819607843137255 0.933333333333333 1" />
      </material>
    </visual>
    <collision>
      <origin
        xyz="0 0 0"
        rpy="0 0 0" />
      <geometry>
        <mesh
          filename="package://segway_description/meshes/chejia_link.STL" />
      </geometry>
    </collision>
  </link>
  <link
    name="zhuanxiangjia_Link">
    <inertial>
      <origin
        xyz="0.00350625991709064 -0.184876810131571 -0.22368381667265"
        rpy="0 0 0" />
      <mass
        value="0.636763996187421" />
      <inertia
        ixx="0.000522373966033037"
        ixy="6.88842321153043E-11"
        ixz="-2.55687287488004E-10"
        iyy="0.000692728712644784"
        iyz="1.31394242797586E-12"
        izz="0.000643891365515844" />
    </inertial>
    <visual>
      <origin
        xyz="0 0 0"
        rpy="0 0 0" />
      <geometry>
        <mesh
          filename="package://segway_description/meshes/zhuanxiangjia_Link.STL" />
      </geometry>
      <material
        name="">
        <color
          rgba="0.792156862745098 0.819607843137255 0.933333333333333 1" />
      </material>
    </visual>
    <collision>
      <origin
        xyz="0 0 0"
        rpy="0 0 0" />
      <geometry>
        <mesh
          filename="package://segway_description/meshes/zhuanxiangjia_Link.STL" />
      </geometry>
    </collision>
  </link>
  <joint
    name="zhuanxiangjia_joint"
    type="revolute">
    <origin
      xyz="0 0 0"
      rpy="1.5708 0 0" />
    <parent
      link="chejia_link" />
    <child
      link="zhuanxiangjia_Link" />
    <axis
      xyz="0 -1 0" />
    <limit
      lower="0"
      upper="0"
      effort="0"
      velocity="0" />
  </joint>
  <link
    name="zuoqianlun_Link">
    <inertial>
      <origin
        xyz="-0.18003195018567 0.0161203758776952 -0.0161713179715041"
        rpy="0 0 0" />
      <mass
        value="0.379124506048444" />
      <inertia
        ixx="0.00135623331658277"
        ixy="-2.05858146537997E-08"
        ixz="2.75425144310775E-07"
        iyy="0.00074553860560749"
        iyz="-2.05160697747808E-08"
        izz="0.000744863292198173" />
    </inertial>
    <visual>
      <origin
        xyz="0 0 0"
        rpy="0 0 0" />
      <geometry>
        <mesh
          filename="package://segway_description/meshes/zuoqianlun_Link.STL" />
      </geometry>
      <material
        name="">
        <color
          rgba="0.792156862745098 0.819607843137255 0.933333333333333 1" />
      </material>
    </visual>
    <collision>
      <origin
        xyz="0 0 0"
        rpy="0 0 0" />
      <geometry>
        <mesh
          filename="package://segway_description/meshes/zuoqianlun_Link.STL" />
      </geometry>
    </collision>
  </link>
  <joint
    name="zuoqianlun_joint"
    type="continuous">
    <origin
      xyz="-0.092435 -0.21283 -0.24243"
      rpy="2.9877 0 0" />
    <parent
      link="zhuanxiangjia_Link" />
    <child
      link="zuoqianlun_Link" />
    <axis
      xyz="1 0 0" />
  </joint>
  <link
    name="youqianlun_Link">
    <inertial>
      <origin
        xyz="-0.180031949902314 0.0161203458684245 -0.0161712883250444"
        rpy="0 0 0" />
      <mass
        value="0.37912408551256" />
      <inertia
        ixx="0.0013562336762928"
        ixy="-2.05946493125457E-08"
        ixz="2.75615782692675E-07"
        iyy="0.0007455386716045"
        iyz="-2.12571382999838E-08"
        izz="0.000744862395561634" />
    </inertial>
    <visual>
      <origin
        xyz="0 0 0"
        rpy="0 0 0" />
      <geometry>
        <mesh
          filename="package://segway_description/meshes/youqianlun_Link.STL" />
      </geometry>
      <material
        name="">
        <color
          rgba="0.792156862745098 0.819607843137255 0.933333333333333 1" />
      </material>
    </visual>
    <collision>
      <origin
        xyz="0 0 0"
        rpy="0 0 0" />
      <geometry>
        <mesh
          filename="package://segway_description/meshes/youqianlun_Link.STL" />
      </geometry>
    </collision>
  </link>
  <joint
    name="youqianlun_joint"
    type="continuous">
    <origin
      xyz="0.099447 -0.24433 -0.20905"
      rpy="-1.6671 0 3.1416" />
    <parent
      link="zhuanxiangjia_Link" />
    <child
      link="youqianlun_Link" />
    <axis
      xyz="1 0 0" />
  </joint>
  <link
    name="zuohoulun_Link">
    <inertial>
      <origin
        xyz="-0.205721407122161 4.72112875317676E-05 9.00201436271342E-06"
        rpy="0 0 0" />
      <mass
        value="0.634779873374433" />
      <inertia
        ixx="0.00181854534335576"
        ixy="3.33041385279325E-07"
        ixz="-2.8378478388468E-07"
        iyy="0.00101390067982028"
        iyz="-5.2299696505564E-09"
        izz="0.00101270577373137" />
    </inertial>
    <visual>
      <origin
        xyz="0 0 0"
        rpy="0 0 0" />
      <geometry>
        <mesh
          filename="package://segway_description/meshes/zuohoulun_Link.STL" />
      </geometry>
      <material
        name="">
        <color
          rgba="0.792156862745098 0.819607843137255 0.933333333333333 1" />
      </material>
    </visual>
    <collision>
      <origin
        xyz="0 0 0"
        rpy="0 0 0" />
      <geometry>
        <mesh
          filename="package://segway_description/meshes/zuohoulun_Link.STL" />
      </geometry>
    </collision>
  </link>
  <joint
    name="zuohoulun_joint"
    type="continuous">
    <origin
      xyz="-0.058831 -0.23219 -0.22848"
      rpy="1.5708 0 0" />
    <parent
      link="chejia_link" />
    <child
      link="zuohoulun_Link" />
    <axis
      xyz="1 0 0" />
  </joint>
  <link
    name="youhoulun_Link">
    <inertial>
      <origin
        xyz="-0.205721415016193 4.72492608288855E-05 9.01686700283122E-06"
        rpy="0 0 0" />
      <mass
        value="0.634778552429949" />
      <inertia
        ixx="0.00181854505148151"
        ixy="3.32515010548019E-07"
        ixz="-2.83394847813244E-07"
        iyy="0.00101390105479182"
        iyz="-5.03852728516005E-09"
        izz="0.00101270465329001" />
    </inertial>
    <visual>
      <origin
        xyz="0 0 0"
        rpy="0 0 0" />
      <geometry>
        <mesh
          filename="package://segway_description/meshes/youhoulun_Link.STL" />
      </geometry>
      <material
        name="">
        <color
          rgba="0.792156862745098 0.819607843137255 0.933333333333333 1" />
      </material>
    </visual>
    <collision>
      <origin
        xyz="0 0 0"
        rpy="0 0 0" />
      <geometry>
        <mesh
          filename="package://segway_description/meshes/youhoulun_Link.STL" />
      </geometry>
    </collision>
  </link>
  <joint
    name="youhoulun_joint"
    type="continuous">
    <origin
      xyz="0.065844 -0.23219 -0.22848"
      rpy="0.17453 0 -3.1416" />
    <parent
      link="chejia_link" />
    <child
      link="youhoulun_Link" />
    <axis
      xyz="1 0 0" />
  </joint>
</robot>
